# 错误处理

## 一. 内建的错误类型

[Built-in Exceptions — Python 3.11.1 documentation](https://docs.python.org/3/library/exceptions.html#exception-hierarchy)

## 二. 定义错误类型

Python的错误其实也是class，所有的错误类型都继承自`BaseException`。

自定义异常类应该总是继承自内置的 `Exception` 类， 或者是继承自那些本身就是从 `Exception` 继承而来的类。 尽管所有类同时也继承自 `BaseException` ，但你不应该使用这个基类来定义新的异常。 `BaseException` 是为系统退出异常而保留的，比如 `KeyboardInterrupt` 或 `SystemExit` 以及其他那些会给应用发送信号而退出的异常。 因此，捕获这些异常本身没什么意义。 这样的话，假如你继承 `BaseException` 可能会导致你的自定义异常不会被捕获而直接发送信号退出程序运行。

在程序中引入自定义异常可以使得你的代码更具可读性，能清晰显示谁应该阅读这个代码。 还有一种设计是将自定义异常通过继承组合起来。在复杂应用程序中，使用基类来分组各种异常类也是很有用的。它可以让用户捕获一个范围很窄的特定异常，比如下面这样的：

```python
try:
    s.send(msg)
except ProtocolError:
    ...
```

你还能捕获更大范围的异常，就像下面这样：

```python
try:
    s.send(msg)
except NetworkError:
    ...
```

如果你想定义的新异常重写了 `__init__()` 方法， 确保你使用所有参数调用 `Exception.__init__()` ，例如：

```python
class CustomError(Exception):
    def __init__(self, message, status):
        super().__init__(message, status)
        self.message = message
        self.status = status
```

看上去有点奇怪，不过Exception的默认行为是接受所有传递的参数并将它们以元组形式存储在 `.args` 属性中. 很多其他函数库和部分Python库默认所有异常都必须有 `.args` 属性， 因此如果你忽略了这一步，你会发现有些时候你定义的新异常不会按照期望运行。 为了演示 `.args` 的使用，考虑下下面这个使用内置的 `RuntimeError` 异常的交互会话，注意看raise语句中使用的参数个数是怎样的：

```python
>>> try:
...     raise RuntimeError('It failed')
... except RuntimeError as e:
...     print(e.args)
...
('It failed',)
>>> try:
...     raise RuntimeError('It failed', 42, 'spam')
... except RuntimeError as e:

...     print(e.args)
...
('It failed', 42, 'spam')
>>>
```

## 三. 错误的捕获

让我们用一个例子来看看`try`的机制：

```python
try:
    print('try...')
    r = 10 / 0
    print('result:', r)
except ZeroDivisionError as e:
    print('except:', e)
finally:
    print('finally...')
print('END')
```

当我们认为某些代码可能会出错时，就可以用`try`来运行这段代码，如果执行出错，则后续代码不会继续执行，而是直接跳转至错误处理代码，即`except`语句块，执行完`except`后，如果有`finally`语句块，则执行`finally`语句块，至此，执行完毕。

### 3.1 捕获异常后抛出另外的异常

为了链接异常，使用 `raise from` 语句来代替简单的 `raise` 语句。 它会让你同时保留两个异常的信息。例如：

```python
 def example():
     try:
             int('N/A')
     except ValueError as e:
             raise RuntimeError('A parsing error occurred') from e
```

调用 `example()` 输出结果：

```txt
Traceback (most recent call last):
  File "E:\opensource-python\hello-project\src\exception\错误.py", line 15, in example
    int('N/A')
ValueError: invalid literal for int() with base 10: 'N/A'

The above exception was the direct cause of the following exception:

Traceback (most recent call last):
  File "E:\opensource-python\hello-project\src\exception\错误.py", line 25, in <module>
    example()
  File "E:\opensource-python\hello-project\src\exception\错误.py", line 17, in example
    raise RuntimeError('A parsing error occurred') from e
RuntimeError: A parsing error occurred

Process finished with exit code 1
```

在设计代码时，在另外一个 `except` 代码块中使用 `raise` 语句的时候你要特别小心了。 大多数情况下，这种 `raise` 语句都应该被改成 `raise from` 语句。也就是说你应该使用下面这种形式：

```python
try:
   ...
except SomeException as e:
   raise DifferentException() from e
```

这样做的原因是你应该显示的将原因链接起来。 也就是说，`DifferentException` 是直接从 `SomeException` 衍生而来。 这种关系可以从回溯结果中看出来。

如果你像下面这样写代码，你仍然会得到一个链接异常， 不过这个并没有很清晰的说明这个异常链到底是内部异常还是某个未知的编程错误。

```python
try:
   ...
except SomeException:
   raise DifferentException()
```

当你使用 `raise from` 语句的话，就很清楚的表明抛出的是第二个异常。

最后一个例子中隐藏异常链信息。 尽管隐藏异常链信息不利于回溯，同时它也丢失了很多有用的调试信息。 不过万事皆平等，有时候只保留适当的信息也是很有用的。

### 3.2 重新抛出异常

简单的使用一个单独的 `rasie` 语句即可，例如：

```python
>>> def example():
...     try:
...             int('N/A')
...     except ValueError:
...             print("Didn't work")
...             raise
...

>>> example()
Didn't work
Traceback (most recent call last):
  File "<stdin>", line 1, in <module>
  File "<stdin>", line 3, in example
ValueError: invalid literal for int() with base 10: 'N/A'
>>>
```

## 四. 输出日志

如果不捕获错误，自然可以让Python解释器来打印出错误堆栈，但程序也被结束了。既然我们能捕获错误，就可以把错误堆栈打印出来，然后分析错误原因，同时，让程序继续执行下去。

Python内置的`logging`模块可以非常容易地记录错误信息：

```python

import logging

def foo(s):
    return 10 / int(s)

def bar(s):
    return foo(s) * 2

def main():
    try:
        bar('0')
    except Exception as e:
        logging.exception(e)

main()
print('END')
```

